[2024-05-16 15:24:50,480] {C:\Users\yat nam chan\PycharmProjects\wenniepedia\users\views.py:42} INFO - User registered: ynchan@gmail.com, IP: 127.0.0.1
[2024-05-16 15:25:07,848] {C:\Users\yat nam chan\PycharmProjects\wenniepedia\users\views.py:65} INFO - User logged in: ynchan@gmail.com, IP: 127.0.0.1
[2024-05-16 15:25:28,001] {C:\Users\yat nam chan\PycharmProjects\wenniepedia\users\views.py:105} INFO - User logged out: ynchan@gmail.com, IP: 127.0.0.1
[2024-05-16 17:36:18,878] {C:\Users\yat nam chan\PycharmProjects\wenniepedia\users\views.py:65} INFO - User logged in: admin@email.com, IP: 127.0.0.1
[2024-05-16 18:19:23,612] {C:\Users\yat nam chan\PycharmProjects\wenniepedia\users\views.py:65} INFO - User logged in: ynchanhk@gmail.com, IP: 127.0.0.1
[2024-05-16 18:19:27,537] {C:\Users\yat nam chan\PycharmProjects\wenniepedia\venv\lib\site-packages\flask\app.py:838} ERROR - Exception on /recipes/add_recipes [GET]
Traceback (most recent call last):
  File "C:\Users\yat nam chan\PycharmProjects\wenniepedia\venv\lib\site-packages\flask\app.py", line 1473, in wsgi_app
    response = self.full_dispatch_request()
  File "C:\Users\yat nam chan\PycharmProjects\wenniepedia\venv\lib\site-packages\flask\app.py", line 882, in full_dispatch_request
    rv = self.handle_user_exception(e)
  File "C:\Users\yat nam chan\PycharmProjects\wenniepedia\venv\lib\site-packages\flask\app.py", line 880, in full_dispatch_request
    rv = self.dispatch_request()
  File "C:\Users\yat nam chan\PycharmProjects\wenniepedia\venv\lib\site-packages\flask\app.py", line 865, in dispatch_request
    return self.ensure_sync(self.view_functions[rule.endpoint])(**view_args)  # type: ignore[no-any-return]
  File "C:\Users\yat nam chan\AppData\Local\Programs\Python\Python39\lib\site-packages\flask_login\utils.py", line 290, in decorated_view
    return current_app.ensure_sync(func)(*args, **kwargs)
  File "C:\Users\yat nam chan\PycharmProjects\wenniepedia\recipes\views.py", line 48, in add_recipes
    return render_template('recipes/add_recipes.html', form=form)
  File "C:\Users\yat nam chan\PycharmProjects\wenniepedia\venv\lib\site-packages\flask\templating.py", line 150, in render_template
    return _render(app, template, context)
  File "C:\Users\yat nam chan\PycharmProjects\wenniepedia\venv\lib\site-packages\flask\templating.py", line 131, in _render
    rv = template.render(context)
  File "C:\Users\yat nam chan\AppData\Local\Programs\Python\Python39\lib\site-packages\jinja2\environment.py", line 1301, in render
    self.environment.handle_exception()
  File "C:\Users\yat nam chan\AppData\Local\Programs\Python\Python39\lib\site-packages\jinja2\environment.py", line 936, in handle_exception
    raise rewrite_traceback_stack(source=source)
  File "C:\Users\yat nam chan\PycharmProjects\wenniepedia\templates\recipes\add_recipes.html", line 69, in top-level template code
    <form action="{{ url_for('recipes_blueprint.add_recipes') }}" method="POST">
  File "C:\Users\yat nam chan\PycharmProjects\wenniepedia\venv\lib\site-packages\flask\app.py", line 1084, in url_for
    return self.handle_url_build_error(error, endpoint, values)
  File "C:\Users\yat nam chan\PycharmProjects\wenniepedia\venv\lib\site-packages\flask\app.py", line 1073, in url_for
    rv = url_adapter.build(  # type: ignore[union-attr]
  File "C:\Users\yat nam chan\PycharmProjects\wenniepedia\venv\lib\site-packages\werkzeug\routing\map.py", line 924, in build
    raise BuildError(endpoint, values, method, self)
werkzeug.routing.exceptions.BuildError: Could not build url for endpoint 'recipes_blueprint.add_recipes'. Did you mean 'recipes.add_recipes' instead?
[2024-05-16 21:30:23,623] {C:\Users\yat nam chan\PycharmProjects\wenniepedia\venv\lib\site-packages\flask\app.py:838} ERROR - Exception on /recipes/your_recipes [GET]
Traceback (most recent call last):
  File "C:\Users\yat nam chan\PycharmProjects\wenniepedia\venv\lib\site-packages\flask\app.py", line 1473, in wsgi_app
    response = self.full_dispatch_request()
  File "C:\Users\yat nam chan\PycharmProjects\wenniepedia\venv\lib\site-packages\flask\app.py", line 882, in full_dispatch_request
    rv = self.handle_user_exception(e)
  File "C:\Users\yat nam chan\PycharmProjects\wenniepedia\venv\lib\site-packages\flask\app.py", line 880, in full_dispatch_request
    rv = self.dispatch_request()
  File "C:\Users\yat nam chan\PycharmProjects\wenniepedia\venv\lib\site-packages\flask\app.py", line 865, in dispatch_request
    return self.ensure_sync(self.view_functions[rule.endpoint])(**view_args)  # type: ignore[no-any-return]
  File "C:\Users\yat nam chan\AppData\Local\Programs\Python\Python39\lib\site-packages\flask_login\utils.py", line 290, in decorated_view
    return current_app.ensure_sync(func)(*args, **kwargs)
  File "C:\Users\yat nam chan\PycharmProjects\wenniepedia\recipes\views.py", line 30, in your_recipes
    return render_template('recipes/your_recipes.html', recipes=recipes)
  File "C:\Users\yat nam chan\PycharmProjects\wenniepedia\venv\lib\site-packages\flask\templating.py", line 150, in render_template
    return _render(app, template, context)
  File "C:\Users\yat nam chan\PycharmProjects\wenniepedia\venv\lib\site-packages\flask\templating.py", line 131, in _render
    rv = template.render(context)
  File "C:\Users\yat nam chan\AppData\Local\Programs\Python\Python39\lib\site-packages\jinja2\environment.py", line 1301, in render
    self.environment.handle_exception()
  File "C:\Users\yat nam chan\AppData\Local\Programs\Python\Python39\lib\site-packages\jinja2\environment.py", line 936, in handle_exception
    raise rewrite_traceback_stack(source=source)
  File "C:\Users\yat nam chan\PycharmProjects\wenniepedia\templates\recipes\your_recipes.html", line 106, in top-level template code
    window.location.href = "{{ url_for('recipes.delete_recipe', recipe_id=" + recipeId + ") }}";
  File "C:\Users\yat nam chan\PycharmProjects\wenniepedia\venv\lib\site-packages\flask\app.py", line 1073, in url_for
    rv = url_adapter.build(  # type: ignore[union-attr]
  File "C:\Users\yat nam chan\PycharmProjects\wenniepedia\venv\lib\site-packages\werkzeug\routing\map.py", line 922, in build
    rv = self._partial_build(endpoint, values, method, append_unknown)
  File "C:\Users\yat nam chan\PycharmProjects\wenniepedia\venv\lib\site-packages\werkzeug\routing\map.py", line 801, in _partial_build
    rv = self._partial_build(
  File "C:\Users\yat nam chan\PycharmProjects\wenniepedia\venv\lib\site-packages\werkzeug\routing\map.py", line 814, in _partial_build
    build_rv = rule.build(values, append_unknown)
  File "C:\Users\yat nam chan\PycharmProjects\wenniepedia\venv\lib\site-packages\werkzeug\routing\rules.py", line 839, in build
    return self._build_unknown(**values)
  File "<werkzeug routing>", line 1, in <builder:'/recipes/delete_recipe, <int:recipe_id>'>
  File "C:\Users\yat nam chan\PycharmProjects\wenniepedia\venv\lib\site-packages\werkzeug\routing\converters.py", line 163, in to_url
    value_str = str(self.num_convert(value))
ValueError: invalid literal for int() with base 10: ' + recipeId + '
[2024-05-16 21:39:46,126] {C:\Users\yat nam chan\PycharmProjects\wenniepedia\venv\lib\site-packages\flask\app.py:838} ERROR - Exception on /recipes/your_recipes [GET]
Traceback (most recent call last):
  File "C:\Users\yat nam chan\PycharmProjects\wenniepedia\venv\lib\site-packages\flask\app.py", line 1473, in wsgi_app
    response = self.full_dispatch_request()
  File "C:\Users\yat nam chan\PycharmProjects\wenniepedia\venv\lib\site-packages\flask\app.py", line 882, in full_dispatch_request
    rv = self.handle_user_exception(e)
  File "C:\Users\yat nam chan\PycharmProjects\wenniepedia\venv\lib\site-packages\flask\app.py", line 880, in full_dispatch_request
    rv = self.dispatch_request()
  File "C:\Users\yat nam chan\PycharmProjects\wenniepedia\venv\lib\site-packages\flask\app.py", line 865, in dispatch_request
    return self.ensure_sync(self.view_functions[rule.endpoint])(**view_args)  # type: ignore[no-any-return]
  File "C:\Users\yat nam chan\AppData\Local\Programs\Python\Python39\lib\site-packages\flask_login\utils.py", line 290, in decorated_view
    return current_app.ensure_sync(func)(*args, **kwargs)
  File "C:\Users\yat nam chan\PycharmProjects\wenniepedia\recipes\views.py", line 30, in your_recipes
    return render_template('recipes/your_recipes.html', recipes=recipes)
  File "C:\Users\yat nam chan\PycharmProjects\wenniepedia\venv\lib\site-packages\flask\templating.py", line 150, in render_template
    return _render(app, template, context)
  File "C:\Users\yat nam chan\PycharmProjects\wenniepedia\venv\lib\site-packages\flask\templating.py", line 131, in _render
    rv = template.render(context)
  File "C:\Users\yat nam chan\AppData\Local\Programs\Python\Python39\lib\site-packages\jinja2\environment.py", line 1301, in render
    self.environment.handle_exception()
  File "C:\Users\yat nam chan\AppData\Local\Programs\Python\Python39\lib\site-packages\jinja2\environment.py", line 936, in handle_exception
    raise rewrite_traceback_stack(source=source)
  File "C:\Users\yat nam chan\PycharmProjects\wenniepedia\templates\recipes\your_recipes.html", line 106, in top-level template code
    window.location.href ="{{ url_for('recipes.delete_recipe' ,recipe_id=recipeId)}}" + recipeId;
  File "C:\Users\yat nam chan\PycharmProjects\wenniepedia\venv\lib\site-packages\flask\app.py", line 1073, in url_for
    rv = url_adapter.build(  # type: ignore[union-attr]
  File "C:\Users\yat nam chan\PycharmProjects\wenniepedia\venv\lib\site-packages\werkzeug\routing\map.py", line 922, in build
    rv = self._partial_build(endpoint, values, method, append_unknown)
  File "C:\Users\yat nam chan\PycharmProjects\wenniepedia\venv\lib\site-packages\werkzeug\routing\map.py", line 801, in _partial_build
    rv = self._partial_build(
  File "C:\Users\yat nam chan\PycharmProjects\wenniepedia\venv\lib\site-packages\werkzeug\routing\map.py", line 814, in _partial_build
    build_rv = rule.build(values, append_unknown)
  File "C:\Users\yat nam chan\PycharmProjects\wenniepedia\venv\lib\site-packages\werkzeug\routing\rules.py", line 839, in build
    return self._build_unknown(**values)
  File "<werkzeug routing>", line 1, in <builder:'/recipes/delete_recipe, <int:recipe_id>'>
  File "C:\Users\yat nam chan\PycharmProjects\wenniepedia\venv\lib\site-packages\werkzeug\routing\converters.py", line 163, in to_url
    value_str = str(self.num_convert(value))
jinja2.exceptions.UndefinedError: 'recipeId' is undefined
[2024-05-16 21:41:15,136] {C:\Users\yat nam chan\PycharmProjects\wenniepedia\venv\lib\site-packages\flask\app.py:838} ERROR - Exception on /recipes/your_recipes [GET]
Traceback (most recent call last):
  File "C:\Users\yat nam chan\PycharmProjects\wenniepedia\venv\lib\site-packages\flask\app.py", line 1473, in wsgi_app
    response = self.full_dispatch_request()
  File "C:\Users\yat nam chan\PycharmProjects\wenniepedia\venv\lib\site-packages\flask\app.py", line 882, in full_dispatch_request
    rv = self.handle_user_exception(e)
  File "C:\Users\yat nam chan\PycharmProjects\wenniepedia\venv\lib\site-packages\flask\app.py", line 880, in full_dispatch_request
    rv = self.dispatch_request()
  File "C:\Users\yat nam chan\PycharmProjects\wenniepedia\venv\lib\site-packages\flask\app.py", line 865, in dispatch_request
    return self.ensure_sync(self.view_functions[rule.endpoint])(**view_args)  # type: ignore[no-any-return]
  File "C:\Users\yat nam chan\AppData\Local\Programs\Python\Python39\lib\site-packages\flask_login\utils.py", line 290, in decorated_view
    return current_app.ensure_sync(func)(*args, **kwargs)
  File "C:\Users\yat nam chan\PycharmProjects\wenniepedia\recipes\views.py", line 30, in your_recipes
    return render_template('recipes/your_recipes.html', recipes=recipes)
  File "C:\Users\yat nam chan\PycharmProjects\wenniepedia\venv\lib\site-packages\flask\templating.py", line 150, in render_template
    return _render(app, template, context)
  File "C:\Users\yat nam chan\PycharmProjects\wenniepedia\venv\lib\site-packages\flask\templating.py", line 131, in _render
    rv = template.render(context)
  File "C:\Users\yat nam chan\AppData\Local\Programs\Python\Python39\lib\site-packages\jinja2\environment.py", line 1301, in render
    self.environment.handle_exception()
  File "C:\Users\yat nam chan\AppData\Local\Programs\Python\Python39\lib\site-packages\jinja2\environment.py", line 936, in handle_exception
    raise rewrite_traceback_stack(source=source)
  File "C:\Users\yat nam chan\PycharmProjects\wenniepedia\templates\recipes\your_recipes.html", line 106, in top-level template code
    window.location.href ="{{ url_for('recipes.delete_recipe' ,recipe_id=recipe.id)}}" + recipeId;
  File "C:\Users\yat nam chan\AppData\Local\Programs\Python\Python39\lib\site-packages\jinja2\environment.py", line 485, in getattr
    return getattr(obj, attribute)
jinja2.exceptions.UndefinedError: 'recipe' is undefined
[2024-05-16 21:57:25,163] {C:\Users\yat nam chan\PycharmProjects\wenniepedia\venv\lib\site-packages\flask\app.py:838} ERROR - Exception on /recipes/your_recipes [GET]
Traceback (most recent call last):
  File "C:\Users\yat nam chan\PycharmProjects\wenniepedia\venv\lib\site-packages\flask\app.py", line 1473, in wsgi_app
    response = self.full_dispatch_request()
  File "C:\Users\yat nam chan\PycharmProjects\wenniepedia\venv\lib\site-packages\flask\app.py", line 882, in full_dispatch_request
    rv = self.handle_user_exception(e)
  File "C:\Users\yat nam chan\PycharmProjects\wenniepedia\venv\lib\site-packages\flask\app.py", line 880, in full_dispatch_request
    rv = self.dispatch_request()
  File "C:\Users\yat nam chan\PycharmProjects\wenniepedia\venv\lib\site-packages\flask\app.py", line 865, in dispatch_request
    return self.ensure_sync(self.view_functions[rule.endpoint])(**view_args)  # type: ignore[no-any-return]
  File "C:\Users\yat nam chan\AppData\Local\Programs\Python\Python39\lib\site-packages\flask_login\utils.py", line 290, in decorated_view
    return current_app.ensure_sync(func)(*args, **kwargs)
  File "C:\Users\yat nam chan\PycharmProjects\wenniepedia\recipes\views.py", line 30, in your_recipes
    return render_template('recipes/your_recipes.html', recipes=recipes)
  File "C:\Users\yat nam chan\PycharmProjects\wenniepedia\venv\lib\site-packages\flask\templating.py", line 150, in render_template
    return _render(app, template, context)
  File "C:\Users\yat nam chan\PycharmProjects\wenniepedia\venv\lib\site-packages\flask\templating.py", line 131, in _render
    rv = template.render(context)
  File "C:\Users\yat nam chan\AppData\Local\Programs\Python\Python39\lib\site-packages\jinja2\environment.py", line 1301, in render
    self.environment.handle_exception()
  File "C:\Users\yat nam chan\AppData\Local\Programs\Python\Python39\lib\site-packages\jinja2\environment.py", line 936, in handle_exception
    raise rewrite_traceback_stack(source=source)
  File "C:\Users\yat nam chan\PycharmProjects\wenniepedia\templates\recipes\your_recipes.html", line 76, in top-level template code
    <input type="hidden" name="csrf_token" value="{{ csrf_token() }}">
  File "C:\Users\yat nam chan\AppData\Local\Programs\Python\Python39\lib\site-packages\jinja2\utils.py", line 83, in from_obj
    if hasattr(obj, "jinja_pass_arg"):
jinja2.exceptions.UndefinedError: 'csrf_token' is undefined
[2024-05-16 21:57:28,912] {C:\Users\yat nam chan\PycharmProjects\wenniepedia\venv\lib\site-packages\flask\app.py:838} ERROR - Exception on /recipes/your_recipes [GET]
Traceback (most recent call last):
  File "C:\Users\yat nam chan\PycharmProjects\wenniepedia\venv\lib\site-packages\flask\app.py", line 1473, in wsgi_app
    response = self.full_dispatch_request()
  File "C:\Users\yat nam chan\PycharmProjects\wenniepedia\venv\lib\site-packages\flask\app.py", line 882, in full_dispatch_request
    rv = self.handle_user_exception(e)
  File "C:\Users\yat nam chan\PycharmProjects\wenniepedia\venv\lib\site-packages\flask\app.py", line 880, in full_dispatch_request
    rv = self.dispatch_request()
  File "C:\Users\yat nam chan\PycharmProjects\wenniepedia\venv\lib\site-packages\flask\app.py", line 865, in dispatch_request
    return self.ensure_sync(self.view_functions[rule.endpoint])(**view_args)  # type: ignore[no-any-return]
  File "C:\Users\yat nam chan\AppData\Local\Programs\Python\Python39\lib\site-packages\flask_login\utils.py", line 290, in decorated_view
    return current_app.ensure_sync(func)(*args, **kwargs)
  File "C:\Users\yat nam chan\PycharmProjects\wenniepedia\recipes\views.py", line 30, in your_recipes
    return render_template('recipes/your_recipes.html', recipes=recipes)
  File "C:\Users\yat nam chan\PycharmProjects\wenniepedia\venv\lib\site-packages\flask\templating.py", line 150, in render_template
    return _render(app, template, context)
  File "C:\Users\yat nam chan\PycharmProjects\wenniepedia\venv\lib\site-packages\flask\templating.py", line 131, in _render
    rv = template.render(context)
  File "C:\Users\yat nam chan\AppData\Local\Programs\Python\Python39\lib\site-packages\jinja2\environment.py", line 1301, in render
    self.environment.handle_exception()
  File "C:\Users\yat nam chan\AppData\Local\Programs\Python\Python39\lib\site-packages\jinja2\environment.py", line 936, in handle_exception
    raise rewrite_traceback_stack(source=source)
  File "C:\Users\yat nam chan\PycharmProjects\wenniepedia\templates\recipes\your_recipes.html", line 76, in top-level template code
    <input type="hidden" name="csrf_token" value="{{ csrf_token() }}">
  File "C:\Users\yat nam chan\AppData\Local\Programs\Python\Python39\lib\site-packages\jinja2\utils.py", line 83, in from_obj
    if hasattr(obj, "jinja_pass_arg"):
jinja2.exceptions.UndefinedError: 'csrf_token' is undefined
[2024-05-16 22:04:56,186] {C:\Users\yat nam chan\PycharmProjects\wenniepedia\venv\lib\site-packages\flask\app.py:838} ERROR - Exception on /recipes/delete_recipe/6 [GET]
Traceback (most recent call last):
  File "C:\Users\yat nam chan\AppData\Local\Programs\Python\Python39\lib\site-packages\sqlalchemy\engine\base.py", line 1969, in _exec_single_context
    self.dialect.do_execute(
  File "C:\Users\yat nam chan\AppData\Local\Programs\Python\Python39\lib\site-packages\sqlalchemy\engine\default.py", line 922, in do_execute
    cursor.execute(statement, parameters)
sqlite3.OperationalError: no such table: ratings

The above exception was the direct cause of the following exception:

Traceback (most recent call last):
  File "C:\Users\yat nam chan\PycharmProjects\wenniepedia\venv\lib\site-packages\flask\app.py", line 1473, in wsgi_app
    response = self.full_dispatch_request()
  File "C:\Users\yat nam chan\PycharmProjects\wenniepedia\venv\lib\site-packages\flask\app.py", line 882, in full_dispatch_request
    rv = self.handle_user_exception(e)
  File "C:\Users\yat nam chan\PycharmProjects\wenniepedia\venv\lib\site-packages\flask\app.py", line 880, in full_dispatch_request
    rv = self.dispatch_request()
  File "C:\Users\yat nam chan\PycharmProjects\wenniepedia\venv\lib\site-packages\flask\app.py", line 865, in dispatch_request
    return self.ensure_sync(self.view_functions[rule.endpoint])(**view_args)  # type: ignore[no-any-return]
  File "C:\Users\yat nam chan\AppData\Local\Programs\Python\Python39\lib\site-packages\flask_login\utils.py", line 290, in decorated_view
    return current_app.ensure_sync(func)(*args, **kwargs)
  File "C:\Users\yat nam chan\PycharmProjects\wenniepedia\recipes\views.py", line 81, in delete_recipe
    db.session.commit()
  File "C:\Users\yat nam chan\AppData\Local\Programs\Python\Python39\lib\site-packages\sqlalchemy\orm\scoping.py", line 598, in commit
    return self._proxied.commit()
  File "C:\Users\yat nam chan\AppData\Local\Programs\Python\Python39\lib\site-packages\sqlalchemy\orm\session.py", line 1969, in commit
    trans.commit(_to_root=True)
  File "<string>", line 2, in commit
  File "C:\Users\yat nam chan\AppData\Local\Programs\Python\Python39\lib\site-packages\sqlalchemy\orm\state_changes.py", line 139, in _go
    ret_value = fn(self, *arg, **kw)
  File "C:\Users\yat nam chan\AppData\Local\Programs\Python\Python39\lib\site-packages\sqlalchemy\orm\session.py", line 1256, in commit
    self._prepare_impl()
  File "<string>", line 2, in _prepare_impl
  File "C:\Users\yat nam chan\AppData\Local\Programs\Python\Python39\lib\site-packages\sqlalchemy\orm\state_changes.py", line 139, in _go
    ret_value = fn(self, *arg, **kw)
  File "C:\Users\yat nam chan\AppData\Local\Programs\Python\Python39\lib\site-packages\sqlalchemy\orm\session.py", line 1231, in _prepare_impl
    self.session.flush()
  File "C:\Users\yat nam chan\AppData\Local\Programs\Python\Python39\lib\site-packages\sqlalchemy\orm\session.py", line 4312, in flush
    self._flush(objects)
  File "C:\Users\yat nam chan\AppData\Local\Programs\Python\Python39\lib\site-packages\sqlalchemy\orm\session.py", line 4448, in _flush
    transaction.rollback(_capture_exception=True)
  File "C:\Users\yat nam chan\AppData\Local\Programs\Python\Python39\lib\site-packages\sqlalchemy\util\langhelpers.py", line 146, in __exit__
    raise exc_value.with_traceback(exc_tb)
  File "C:\Users\yat nam chan\AppData\Local\Programs\Python\Python39\lib\site-packages\sqlalchemy\orm\session.py", line 4408, in _flush
    flush_context.execute()
  File "C:\Users\yat nam chan\AppData\Local\Programs\Python\Python39\lib\site-packages\sqlalchemy\orm\unitofwork.py", line 442, in execute
    postsort_actions = self._generate_actions()
  File "C:\Users\yat nam chan\AppData\Local\Programs\Python\Python39\lib\site-packages\sqlalchemy\orm\unitofwork.py", line 400, in _generate_actions
    if action.execute(self):
  File "C:\Users\yat nam chan\AppData\Local\Programs\Python\Python39\lib\site-packages\sqlalchemy\orm\unitofwork.py", line 532, in execute
    self.dependency_processor.presort_deletes(uow, delete_states)
  File "C:\Users\yat nam chan\AppData\Local\Programs\Python\Python39\lib\site-packages\sqlalchemy\orm\dependency.py", line 448, in presort_deletes
    history = uowcommit.get_attribute_history(
  File "C:\Users\yat nam chan\AppData\Local\Programs\Python\Python39\lib\site-packages\sqlalchemy\orm\unitofwork.py", line 283, in get_attribute_history
    history = impl.get_history(
  File "C:\Users\yat nam chan\AppData\Local\Programs\Python\Python39\lib\site-packages\sqlalchemy\orm\attributes.py", line 1683, in get_history
    current = self.get(state, dict_, passive=passive)
  File "C:\Users\yat nam chan\AppData\Local\Programs\Python\Python39\lib\site-packages\sqlalchemy\orm\attributes.py", line 1086, in get
    value = self._fire_loader_callables(state, key, passive)
  File "C:\Users\yat nam chan\AppData\Local\Programs\Python\Python39\lib\site-packages\sqlalchemy\orm\attributes.py", line 1121, in _fire_loader_callables
    return self.callable_(state, passive)
  File "C:\Users\yat nam chan\AppData\Local\Programs\Python\Python39\lib\site-packages\sqlalchemy\orm\strategies.py", line 967, in _load_for_state
    return self._emit_lazyload(
  File "C:\Users\yat nam chan\AppData\Local\Programs\Python\Python39\lib\site-packages\sqlalchemy\orm\strategies.py", line 1130, in _emit_lazyload
    result = session.execute(
  File "C:\Users\yat nam chan\AppData\Local\Programs\Python\Python39\lib\site-packages\sqlalchemy\orm\session.py", line 2308, in execute
    return self._execute_internal(
  File "C:\Users\yat nam chan\AppData\Local\Programs\Python\Python39\lib\site-packages\sqlalchemy\orm\session.py", line 2190, in _execute_internal
    result: Result[Any] = compile_state_cls.orm_execute_statement(
  File "C:\Users\yat nam chan\AppData\Local\Programs\Python\Python39\lib\site-packages\sqlalchemy\orm\context.py", line 293, in orm_execute_statement
    result = conn.execute(
  File "C:\Users\yat nam chan\AppData\Local\Programs\Python\Python39\lib\site-packages\sqlalchemy\engine\base.py", line 1416, in execute
    return meth(
  File "C:\Users\yat nam chan\AppData\Local\Programs\Python\Python39\lib\site-packages\sqlalchemy\sql\elements.py", line 516, in _execute_on_connection
    return connection._execute_clauseelement(
  File "C:\Users\yat nam chan\AppData\Local\Programs\Python\Python39\lib\site-packages\sqlalchemy\engine\base.py", line 1639, in _execute_clauseelement
    ret = self._execute_context(
  File "C:\Users\yat nam chan\AppData\Local\Programs\Python\Python39\lib\site-packages\sqlalchemy\engine\base.py", line 1848, in _execute_context
    return self._exec_single_context(
  File "C:\Users\yat nam chan\AppData\Local\Programs\Python\Python39\lib\site-packages\sqlalchemy\engine\base.py", line 1988, in _exec_single_context
    self._handle_dbapi_exception(
  File "C:\Users\yat nam chan\AppData\Local\Programs\Python\Python39\lib\site-packages\sqlalchemy\engine\base.py", line 2343, in _handle_dbapi_exception
    raise sqlalchemy_exception.with_traceback(exc_info[2]) from e
  File "C:\Users\yat nam chan\AppData\Local\Programs\Python\Python39\lib\site-packages\sqlalchemy\engine\base.py", line 1969, in _exec_single_context
    self.dialect.do_execute(
  File "C:\Users\yat nam chan\AppData\Local\Programs\Python\Python39\lib\site-packages\sqlalchemy\engine\default.py", line 922, in do_execute
    cursor.execute(statement, parameters)
sqlalchemy.exc.OperationalError: (sqlite3.OperationalError) no such table: ratings
[SQL: SELECT ratings.user_id AS ratings_user_id, ratings.recipe_id AS ratings_recipe_id, ratings.rating AS ratings_rating 
FROM ratings 
WHERE ? = ratings.recipe_id]
[parameters: (6,)]
(Background on this error at: https://sqlalche.me/e/20/e3q8)
[2024-05-16 22:13:01,592] {C:\Users\yat nam chan\PycharmProjects\wenniepedia\venv\lib\site-packages\flask\app.py:838} ERROR - Exception on /recipes/delete_recipe/6 [GET]
Traceback (most recent call last):
  File "C:\Users\yat nam chan\AppData\Local\Programs\Python\Python39\lib\site-packages\sqlalchemy\engine\base.py", line 1969, in _exec_single_context
    self.dialect.do_execute(
  File "C:\Users\yat nam chan\AppData\Local\Programs\Python\Python39\lib\site-packages\sqlalchemy\engine\default.py", line 922, in do_execute
    cursor.execute(statement, parameters)
sqlite3.OperationalError: no such table: ratings

The above exception was the direct cause of the following exception:

Traceback (most recent call last):
  File "C:\Users\yat nam chan\PycharmProjects\wenniepedia\venv\lib\site-packages\flask\app.py", line 1473, in wsgi_app
    response = self.full_dispatch_request()
  File "C:\Users\yat nam chan\PycharmProjects\wenniepedia\venv\lib\site-packages\flask\app.py", line 882, in full_dispatch_request
    rv = self.handle_user_exception(e)
  File "C:\Users\yat nam chan\PycharmProjects\wenniepedia\venv\lib\site-packages\flask\app.py", line 880, in full_dispatch_request
    rv = self.dispatch_request()
  File "C:\Users\yat nam chan\PycharmProjects\wenniepedia\venv\lib\site-packages\flask\app.py", line 865, in dispatch_request
    return self.ensure_sync(self.view_functions[rule.endpoint])(**view_args)  # type: ignore[no-any-return]
  File "C:\Users\yat nam chan\AppData\Local\Programs\Python\Python39\lib\site-packages\flask_login\utils.py", line 290, in decorated_view
    return current_app.ensure_sync(func)(*args, **kwargs)
  File "C:\Users\yat nam chan\PycharmProjects\wenniepedia\recipes\views.py", line 81, in delete_recipe
    db.session.commit()
  File "C:\Users\yat nam chan\AppData\Local\Programs\Python\Python39\lib\site-packages\sqlalchemy\orm\scoping.py", line 598, in commit
    return self._proxied.commit()
  File "C:\Users\yat nam chan\AppData\Local\Programs\Python\Python39\lib\site-packages\sqlalchemy\orm\session.py", line 1969, in commit
    trans.commit(_to_root=True)
  File "<string>", line 2, in commit
  File "C:\Users\yat nam chan\AppData\Local\Programs\Python\Python39\lib\site-packages\sqlalchemy\orm\state_changes.py", line 139, in _go
    ret_value = fn(self, *arg, **kw)
  File "C:\Users\yat nam chan\AppData\Local\Programs\Python\Python39\lib\site-packages\sqlalchemy\orm\session.py", line 1256, in commit
    self._prepare_impl()
  File "<string>", line 2, in _prepare_impl
  File "C:\Users\yat nam chan\AppData\Local\Programs\Python\Python39\lib\site-packages\sqlalchemy\orm\state_changes.py", line 139, in _go
    ret_value = fn(self, *arg, **kw)
  File "C:\Users\yat nam chan\AppData\Local\Programs\Python\Python39\lib\site-packages\sqlalchemy\orm\session.py", line 1231, in _prepare_impl
    self.session.flush()
  File "C:\Users\yat nam chan\AppData\Local\Programs\Python\Python39\lib\site-packages\sqlalchemy\orm\session.py", line 4312, in flush
    self._flush(objects)
  File "C:\Users\yat nam chan\AppData\Local\Programs\Python\Python39\lib\site-packages\sqlalchemy\orm\session.py", line 4448, in _flush
    transaction.rollback(_capture_exception=True)
  File "C:\Users\yat nam chan\AppData\Local\Programs\Python\Python39\lib\site-packages\sqlalchemy\util\langhelpers.py", line 146, in __exit__
    raise exc_value.with_traceback(exc_tb)
  File "C:\Users\yat nam chan\AppData\Local\Programs\Python\Python39\lib\site-packages\sqlalchemy\orm\session.py", line 4408, in _flush
    flush_context.execute()
  File "C:\Users\yat nam chan\AppData\Local\Programs\Python\Python39\lib\site-packages\sqlalchemy\orm\unitofwork.py", line 442, in execute
    postsort_actions = self._generate_actions()
  File "C:\Users\yat nam chan\AppData\Local\Programs\Python\Python39\lib\site-packages\sqlalchemy\orm\unitofwork.py", line 400, in _generate_actions
    if action.execute(self):
  File "C:\Users\yat nam chan\AppData\Local\Programs\Python\Python39\lib\site-packages\sqlalchemy\orm\unitofwork.py", line 532, in execute
    self.dependency_processor.presort_deletes(uow, delete_states)
  File "C:\Users\yat nam chan\AppData\Local\Programs\Python\Python39\lib\site-packages\sqlalchemy\orm\dependency.py", line 448, in presort_deletes
    history = uowcommit.get_attribute_history(
  File "C:\Users\yat nam chan\AppData\Local\Programs\Python\Python39\lib\site-packages\sqlalchemy\orm\unitofwork.py", line 283, in get_attribute_history
    history = impl.get_history(
  File "C:\Users\yat nam chan\AppData\Local\Programs\Python\Python39\lib\site-packages\sqlalchemy\orm\attributes.py", line 1683, in get_history
    current = self.get(state, dict_, passive=passive)
  File "C:\Users\yat nam chan\AppData\Local\Programs\Python\Python39\lib\site-packages\sqlalchemy\orm\attributes.py", line 1086, in get
    value = self._fire_loader_callables(state, key, passive)
  File "C:\Users\yat nam chan\AppData\Local\Programs\Python\Python39\lib\site-packages\sqlalchemy\orm\attributes.py", line 1121, in _fire_loader_callables
    return self.callable_(state, passive)
  File "C:\Users\yat nam chan\AppData\Local\Programs\Python\Python39\lib\site-packages\sqlalchemy\orm\strategies.py", line 967, in _load_for_state
    return self._emit_lazyload(
  File "C:\Users\yat nam chan\AppData\Local\Programs\Python\Python39\lib\site-packages\sqlalchemy\orm\strategies.py", line 1130, in _emit_lazyload
    result = session.execute(
  File "C:\Users\yat nam chan\AppData\Local\Programs\Python\Python39\lib\site-packages\sqlalchemy\orm\session.py", line 2308, in execute
    return self._execute_internal(
  File "C:\Users\yat nam chan\AppData\Local\Programs\Python\Python39\lib\site-packages\sqlalchemy\orm\session.py", line 2190, in _execute_internal
    result: Result[Any] = compile_state_cls.orm_execute_statement(
  File "C:\Users\yat nam chan\AppData\Local\Programs\Python\Python39\lib\site-packages\sqlalchemy\orm\context.py", line 293, in orm_execute_statement
    result = conn.execute(
  File "C:\Users\yat nam chan\AppData\Local\Programs\Python\Python39\lib\site-packages\sqlalchemy\engine\base.py", line 1416, in execute
    return meth(
  File "C:\Users\yat nam chan\AppData\Local\Programs\Python\Python39\lib\site-packages\sqlalchemy\sql\elements.py", line 516, in _execute_on_connection
    return connection._execute_clauseelement(
  File "C:\Users\yat nam chan\AppData\Local\Programs\Python\Python39\lib\site-packages\sqlalchemy\engine\base.py", line 1639, in _execute_clauseelement
    ret = self._execute_context(
  File "C:\Users\yat nam chan\AppData\Local\Programs\Python\Python39\lib\site-packages\sqlalchemy\engine\base.py", line 1848, in _execute_context
    return self._exec_single_context(
  File "C:\Users\yat nam chan\AppData\Local\Programs\Python\Python39\lib\site-packages\sqlalchemy\engine\base.py", line 1988, in _exec_single_context
    self._handle_dbapi_exception(
  File "C:\Users\yat nam chan\AppData\Local\Programs\Python\Python39\lib\site-packages\sqlalchemy\engine\base.py", line 2343, in _handle_dbapi_exception
    raise sqlalchemy_exception.with_traceback(exc_info[2]) from e
  File "C:\Users\yat nam chan\AppData\Local\Programs\Python\Python39\lib\site-packages\sqlalchemy\engine\base.py", line 1969, in _exec_single_context
    self.dialect.do_execute(
  File "C:\Users\yat nam chan\AppData\Local\Programs\Python\Python39\lib\site-packages\sqlalchemy\engine\default.py", line 922, in do_execute
    cursor.execute(statement, parameters)
sqlalchemy.exc.OperationalError: (sqlite3.OperationalError) no such table: ratings
[SQL: SELECT ratings.user_id AS ratings_user_id, ratings.recipe_id AS ratings_recipe_id, ratings.rating AS ratings_rating 
FROM ratings 
WHERE ? = ratings.recipe_id]
[parameters: (6,)]
(Background on this error at: https://sqlalche.me/e/20/e3q8)
[2024-05-16 22:22:06,073] {C:\Users\yat nam chan\PycharmProjects\wenniepedia\users\views.py:42} INFO - User registered: ynchan@gmail.com, IP: 127.0.0.1
[2024-05-16 22:22:51,175] {C:\Users\yat nam chan\PycharmProjects\wenniepedia\users\views.py:65} INFO - User logged in: ynchan@gmail.com, IP: 127.0.0.1
[2024-05-16 22:24:24,199] {C:\Users\yat nam chan\PycharmProjects\wenniepedia\venv\lib\site-packages\flask\app.py:838} ERROR - Exception on /recipes/delete_recipe/5 [GET]
Traceback (most recent call last):
  File "C:\Users\yat nam chan\AppData\Local\Programs\Python\Python39\lib\site-packages\sqlalchemy\engine\base.py", line 1938, in _exec_single_context
    self.dialect.do_executemany(
  File "C:\Users\yat nam chan\AppData\Local\Programs\Python\Python39\lib\site-packages\sqlalchemy\engine\default.py", line 919, in do_executemany
    cursor.executemany(statement, parameters)
sqlite3.IntegrityError: NOT NULL constraint failed: ingredients.recipe_id

The above exception was the direct cause of the following exception:

Traceback (most recent call last):
  File "C:\Users\yat nam chan\PycharmProjects\wenniepedia\venv\lib\site-packages\flask\app.py", line 1473, in wsgi_app
    response = self.full_dispatch_request()
  File "C:\Users\yat nam chan\PycharmProjects\wenniepedia\venv\lib\site-packages\flask\app.py", line 882, in full_dispatch_request
    rv = self.handle_user_exception(e)
  File "C:\Users\yat nam chan\PycharmProjects\wenniepedia\venv\lib\site-packages\flask\app.py", line 880, in full_dispatch_request
    rv = self.dispatch_request()
  File "C:\Users\yat nam chan\PycharmProjects\wenniepedia\venv\lib\site-packages\flask\app.py", line 865, in dispatch_request
    return self.ensure_sync(self.view_functions[rule.endpoint])(**view_args)  # type: ignore[no-any-return]
  File "C:\Users\yat nam chan\AppData\Local\Programs\Python\Python39\lib\site-packages\flask_login\utils.py", line 290, in decorated_view
    return current_app.ensure_sync(func)(*args, **kwargs)
  File "C:\Users\yat nam chan\PycharmProjects\wenniepedia\recipes\views.py", line 81, in delete_recipe
    db.session.commit()
  File "C:\Users\yat nam chan\AppData\Local\Programs\Python\Python39\lib\site-packages\sqlalchemy\orm\scoping.py", line 598, in commit
    return self._proxied.commit()
  File "C:\Users\yat nam chan\AppData\Local\Programs\Python\Python39\lib\site-packages\sqlalchemy\orm\session.py", line 1969, in commit
    trans.commit(_to_root=True)
  File "<string>", line 2, in commit
  File "C:\Users\yat nam chan\AppData\Local\Programs\Python\Python39\lib\site-packages\sqlalchemy\orm\state_changes.py", line 139, in _go
    ret_value = fn(self, *arg, **kw)
  File "C:\Users\yat nam chan\AppData\Local\Programs\Python\Python39\lib\site-packages\sqlalchemy\orm\session.py", line 1256, in commit
    self._prepare_impl()
  File "<string>", line 2, in _prepare_impl
  File "C:\Users\yat nam chan\AppData\Local\Programs\Python\Python39\lib\site-packages\sqlalchemy\orm\state_changes.py", line 139, in _go
    ret_value = fn(self, *arg, **kw)
  File "C:\Users\yat nam chan\AppData\Local\Programs\Python\Python39\lib\site-packages\sqlalchemy\orm\session.py", line 1231, in _prepare_impl
    self.session.flush()
  File "C:\Users\yat nam chan\AppData\Local\Programs\Python\Python39\lib\site-packages\sqlalchemy\orm\session.py", line 4312, in flush
    self._flush(objects)
  File "C:\Users\yat nam chan\AppData\Local\Programs\Python\Python39\lib\site-packages\sqlalchemy\orm\session.py", line 4448, in _flush
    transaction.rollback(_capture_exception=True)
  File "C:\Users\yat nam chan\AppData\Local\Programs\Python\Python39\lib\site-packages\sqlalchemy\util\langhelpers.py", line 146, in __exit__
    raise exc_value.with_traceback(exc_tb)
  File "C:\Users\yat nam chan\AppData\Local\Programs\Python\Python39\lib\site-packages\sqlalchemy\orm\session.py", line 4408, in _flush
    flush_context.execute()
  File "C:\Users\yat nam chan\AppData\Local\Programs\Python\Python39\lib\site-packages\sqlalchemy\orm\unitofwork.py", line 466, in execute
    rec.execute(self)
  File "C:\Users\yat nam chan\AppData\Local\Programs\Python\Python39\lib\site-packages\sqlalchemy\orm\unitofwork.py", line 642, in execute
    util.preloaded.orm_persistence.save_obj(
  File "C:\Users\yat nam chan\AppData\Local\Programs\Python\Python39\lib\site-packages\sqlalchemy\orm\persistence.py", line 85, in save_obj
    _emit_update_statements(
  File "C:\Users\yat nam chan\AppData\Local\Programs\Python\Python39\lib\site-packages\sqlalchemy\orm\persistence.py", line 909, in _emit_update_statements
    c = connection.execute(
  File "C:\Users\yat nam chan\AppData\Local\Programs\Python\Python39\lib\site-packages\sqlalchemy\engine\base.py", line 1416, in execute
    return meth(
  File "C:\Users\yat nam chan\AppData\Local\Programs\Python\Python39\lib\site-packages\sqlalchemy\sql\elements.py", line 516, in _execute_on_connection
    return connection._execute_clauseelement(
  File "C:\Users\yat nam chan\AppData\Local\Programs\Python\Python39\lib\site-packages\sqlalchemy\engine\base.py", line 1639, in _execute_clauseelement
    ret = self._execute_context(
  File "C:\Users\yat nam chan\AppData\Local\Programs\Python\Python39\lib\site-packages\sqlalchemy\engine\base.py", line 1848, in _execute_context
    return self._exec_single_context(
  File "C:\Users\yat nam chan\AppData\Local\Programs\Python\Python39\lib\site-packages\sqlalchemy\engine\base.py", line 1988, in _exec_single_context
    self._handle_dbapi_exception(
  File "C:\Users\yat nam chan\AppData\Local\Programs\Python\Python39\lib\site-packages\sqlalchemy\engine\base.py", line 2343, in _handle_dbapi_exception
    raise sqlalchemy_exception.with_traceback(exc_info[2]) from e
  File "C:\Users\yat nam chan\AppData\Local\Programs\Python\Python39\lib\site-packages\sqlalchemy\engine\base.py", line 1938, in _exec_single_context
    self.dialect.do_executemany(
  File "C:\Users\yat nam chan\AppData\Local\Programs\Python\Python39\lib\site-packages\sqlalchemy\engine\default.py", line 919, in do_executemany
    cursor.executemany(statement, parameters)
sqlalchemy.exc.IntegrityError: (sqlite3.IntegrityError) NOT NULL constraint failed: ingredients.recipe_id
[SQL: UPDATE ingredients SET recipe_id=? WHERE ingredients.id = ?]
[parameters: [(None, 18), (None, 19)]]
(Background on this error at: https://sqlalche.me/e/20/gkpj)
[2024-05-16 22:31:26,608] {C:\Users\yat nam chan\PycharmProjects\wenniepedia\venv\lib\site-packages\flask\app.py:838} ERROR - Exception on /recipes/delete_recipe/5 [GET]
Traceback (most recent call last):
  File "C:\Users\yat nam chan\PycharmProjects\wenniepedia\venv\lib\site-packages\flask\app.py", line 1473, in wsgi_app
    response = self.full_dispatch_request()
  File "C:\Users\yat nam chan\PycharmProjects\wenniepedia\venv\lib\site-packages\flask\app.py", line 882, in full_dispatch_request
    rv = self.handle_user_exception(e)
  File "C:\Users\yat nam chan\PycharmProjects\wenniepedia\venv\lib\site-packages\flask\app.py", line 880, in full_dispatch_request
    rv = self.dispatch_request()
  File "C:\Users\yat nam chan\PycharmProjects\wenniepedia\venv\lib\site-packages\flask\app.py", line 865, in dispatch_request
    return self.ensure_sync(self.view_functions[rule.endpoint])(**view_args)  # type: ignore[no-any-return]
  File "C:\Users\yat nam chan\AppData\Local\Programs\Python\Python39\lib\site-packages\flask_login\utils.py", line 290, in decorated_view
    return current_app.ensure_sync(func)(*args, **kwargs)
  File "C:\Users\yat nam chan\PycharmProjects\wenniepedia\recipes\views.py", line 79, in delete_recipe
    ingredients = Ingredient.query.all(recipe_id)
TypeError: all() takes 1 positional argument but 2 were given
[2024-05-16 22:34:55,989] {C:\Users\yat nam chan\PycharmProjects\wenniepedia\venv\lib\site-packages\flask\app.py:838} ERROR - Exception on /recipes/delete_recipe/6 [GET]
Traceback (most recent call last):
  File "C:\Users\yat nam chan\AppData\Local\Programs\Python\Python39\lib\site-packages\sqlalchemy\orm\session.py", line 3494, in delete
    state = attributes.instance_state(instance)
AttributeError: 'list' object has no attribute '_sa_instance_state'

The above exception was the direct cause of the following exception:

Traceback (most recent call last):
  File "C:\Users\yat nam chan\PycharmProjects\wenniepedia\venv\lib\site-packages\flask\app.py", line 1473, in wsgi_app
    response = self.full_dispatch_request()
  File "C:\Users\yat nam chan\PycharmProjects\wenniepedia\venv\lib\site-packages\flask\app.py", line 882, in full_dispatch_request
    rv = self.handle_user_exception(e)
  File "C:\Users\yat nam chan\PycharmProjects\wenniepedia\venv\lib\site-packages\flask\app.py", line 880, in full_dispatch_request
    rv = self.dispatch_request()
  File "C:\Users\yat nam chan\PycharmProjects\wenniepedia\venv\lib\site-packages\flask\app.py", line 865, in dispatch_request
    return self.ensure_sync(self.view_functions[rule.endpoint])(**view_args)  # type: ignore[no-any-return]
  File "C:\Users\yat nam chan\AppData\Local\Programs\Python\Python39\lib\site-packages\flask_login\utils.py", line 290, in decorated_view
    return current_app.ensure_sync(func)(*args, **kwargs)
  File "C:\Users\yat nam chan\PycharmProjects\wenniepedia\recipes\views.py", line 81, in delete_recipe
    db.session.delete(ingredients)
  File "C:\Users\yat nam chan\AppData\Local\Programs\Python\Python39\lib\site-packages\sqlalchemy\orm\scoping.py", line 673, in delete
    return self._proxied.delete(instance)
  File "C:\Users\yat nam chan\AppData\Local\Programs\Python\Python39\lib\site-packages\sqlalchemy\orm\session.py", line 3496, in delete
    raise exc.UnmappedInstanceError(instance) from err
sqlalchemy.orm.exc.UnmappedInstanceError: Class 'builtins.list' is not mapped
[2024-05-16 23:34:19,773] {C:\Users\yat nam chan\PycharmProjects\wenniepedia\venv\lib\site-packages\flask\app.py:838} ERROR - Exception on /recipes/your_recipes [GET]
Traceback (most recent call last):
  File "C:\Users\yat nam chan\PycharmProjects\wenniepedia\venv\lib\site-packages\flask\app.py", line 1473, in wsgi_app
    response = self.full_dispatch_request()
  File "C:\Users\yat nam chan\PycharmProjects\wenniepedia\venv\lib\site-packages\flask\app.py", line 882, in full_dispatch_request
    rv = self.handle_user_exception(e)
  File "C:\Users\yat nam chan\PycharmProjects\wenniepedia\venv\lib\site-packages\flask\app.py", line 880, in full_dispatch_request
    rv = self.dispatch_request()
  File "C:\Users\yat nam chan\PycharmProjects\wenniepedia\venv\lib\site-packages\flask\app.py", line 865, in dispatch_request
    return self.ensure_sync(self.view_functions[rule.endpoint])(**view_args)  # type: ignore[no-any-return]
  File "C:\Users\yat nam chan\AppData\Local\Programs\Python\Python39\lib\site-packages\flask_login\utils.py", line 290, in decorated_view
    return current_app.ensure_sync(func)(*args, **kwargs)
  File "C:\Users\yat nam chan\PycharmProjects\wenniepedia\recipes\views.py", line 30, in your_recipes
    return render_template('recipes/your_recipes.html', recipes=recipes)
  File "C:\Users\yat nam chan\PycharmProjects\wenniepedia\venv\lib\site-packages\flask\templating.py", line 150, in render_template
    return _render(app, template, context)
  File "C:\Users\yat nam chan\PycharmProjects\wenniepedia\venv\lib\site-packages\flask\templating.py", line 131, in _render
    rv = template.render(context)
  File "C:\Users\yat nam chan\AppData\Local\Programs\Python\Python39\lib\site-packages\jinja2\environment.py", line 1301, in render
    self.environment.handle_exception()
  File "C:\Users\yat nam chan\AppData\Local\Programs\Python\Python39\lib\site-packages\jinja2\environment.py", line 936, in handle_exception
    raise rewrite_traceback_stack(source=source)
  File "C:\Users\yat nam chan\PycharmProjects\wenniepedia\templates\recipes\your_recipes.html", line 115, in top-level template code
    <a href="{{ url_for('recipes.edit_recipe', recipe_id=recipe.id) }}" class="edit-button" onclick="return confirm('Are you sure you want to edit this recipe?');">Edit</a>
  File "C:\Users\yat nam chan\PycharmProjects\wenniepedia\venv\lib\site-packages\flask\app.py", line 1084, in url_for
    return self.handle_url_build_error(error, endpoint, values)
  File "C:\Users\yat nam chan\PycharmProjects\wenniepedia\venv\lib\site-packages\flask\app.py", line 1073, in url_for
    rv = url_adapter.build(  # type: ignore[union-attr]
  File "C:\Users\yat nam chan\PycharmProjects\wenniepedia\venv\lib\site-packages\werkzeug\routing\map.py", line 924, in build
    raise BuildError(endpoint, values, method, self)
werkzeug.routing.exceptions.BuildError: Could not build url for endpoint 'recipes.edit_recipe' with values ['recipe_id']. Did you mean 'recipes.delete_recipe' instead?
